Workbook

Sheet How to fill it
B2: 02_sizing — how to fill it in (Assignment 2)
B4: WHICH PROJECT IS THIS ABOUT?
B5: Your team's own project: the customer-support agent your team chose for the course (one of the proposals P1–P8 in the project document, or your own idea). One sheet per team, committed as 02_sizing.xlsx in your Git repository. It is NOT about Paylio: Paylio is the fictional company of the in-class exercise; it only appears in column H of the Inputs tab, to show what a filled-in cell looks like.
B7: WHAT THE SHEET ANSWERS
B8: Is your agent worth building for the company? You get: the net value per year in three scenarios (pessimistic, base, optimistic), an expected value, the comparison with doing nothing and with another project the same team could do, a decision (go / no-go / conditional go), the one assumption that flips the decision, and a build / buy / orchestrate score. Your memo (02_investment_memo.md) explains these numbers in one page.
B10: WHERE YOUR NUMBERS COME FROM
B11: 1) Your company's numbers are in your proposal (table at the bottom of this tab): treat them as measured — they are your company's logs. 2) Orders of magnitude from the Session 2 slides (a human ticket costs €5–15 all-in; an LLM conversation €0.02–0.20): analogy. 3) Everything else is your estimate: write guess, and say in the note how you would check it. Every yellow cell gets a source type and a note.
B13: STEP BY STEP — about one hour, as a team. Type only in the yellow cells.
B14: Step | C14: Where | D14: What to enter | E14: Tip
B15: 1 · Volume and human cost | C15: Inputs, rows 6–9 | D15: Tickets per month; number of support agents; what ONE agent costs the company per year (all-in); the cost of one ticket handled by a human. | E15: From your proposal. Row 10 gives the agent time per ticket from headcount (Paylio: 60 × €45k ÷ 480,000 ≈ €5.6; €10 all-in with team leads, QA and tools); row 11 the tickets per agent per day.
B16: 2 · Your categories | C16: Inputs, A14:A16 and rows 14–16 | D16: Rename the three categories of work your agent deals with — ticket types, requests, incidents, accounts (e.g. P4: refund requests, delivery questions, account issues) — and give each one's share of the volume. | E16: Fewer than three? Set Include = 0 (rows 34–36) for the unused ones.
B17: 3 · Automatable share | C17: Inputs, rows 18–20 | D17: In each category, the share of tickets the agent could handle at all (answerable from the documentation, the policy, the data it can see). | E17: Guess from a sample of tickets — and say how you would check it.
B18: 4 · Deflection realised | C18: Inputs, rows 22–24 | D18: Of those, the share actually resolved without a human once live. | E18: Usually THE assumption that flips the decision: mark it “guess → S4 test”.
B19: 5 · Errors and what they cost | C19: Inputs, rows 26–32 | D19: The error rate per category, and the cost in € of one wrong answer (customer retries, refund leakage, penalty, churn, a legal case). | E19: The costly categories are where a human must stay — that is a scope decision (step 6).
B20: 6 · Scope | C20: Inputs, rows 34–36 | D20: 1 = the agent handles this category, 0 = it does not. | E20: Try 0 on the riskiest category and watch the decision.
B21: 7 · Adoption by quarter | C21: Inputs, rows 39–42 | D21: The share of the deflectable volume actually handled in Q1, Q2, Q3, Q4. | E21: Never 100 % in Q1 — Octopus Energy went from a handful of emails to 34 %, then 45 %.
B22: 8 · AI cost | C22: Inputs, rows 45–46 | D22: The AI cost per conversation (tokens × price) and the retry overhead. | E22: €0.02–0.20 per conversation; recheck token prices the day you fill it in.
B23: 9 · Fixed costs | C23: Inputs, rows 49–56 | D23: Integration, evaluation, supervision (people in the loop, in FTE), monitoring and on-call, re-evaluation when the model changes. | E23: The human in the loop is a cost line, not free.
B24: 10 · The two comparisons | C24: Inputs, rows 59–60 | D24: How much the current process improves each year on its own (do-nothing), and the yearly value of the next-best project the same team could do (name it in the note). | E24: The hurdle is another project, not zero.
B25: 11 · Probabilities | C25: Inputs, row 63 | D25: How likely you find the pessimistic, base and optimistic scenarios. | E25: Must sum to 1 (row 64 checks it).
... B28: 14 · Write the memo | C28: 02_investment_memo.md | D28: Recommendation on line one, the four CFO questions, one line on build / buy / orchestrate. | E28: Same base case as this sheet.
B30: STARTING NUMBERS FROM THE PROJECT DOCUMENT
B31: Proposal | C31: Company numbers | D31: The pain | E31: Kind of value
B32: P1 · HR & payroll SaaS | C32: 2,500 customer companies · 40,000 tickets/month · 60 support agents | D32: 55 % of tickets are “how do I…” questions already answered in the documentation; peaks at month end | E32: Work avoided
B33: P2 · B2B payments fintech | C33: 800 merchants · 12,000 tickets/month | D33: Agents spend 40 % of handling time reading transaction history and past tickets | E33: Time saved (copilot)
B34: P3 · DevOps / observability | C34: 5,000 accounts · tickets ×10 during incidents (normal volume not given: estimate it) | D34: During an outage, 70 % of tickets say the same thing | E34: Incident load — tickets per incident × incidents a year
B35: P4 · E-commerce logistics | C35: 15,000 merchants · 25,000 tickets/month | D35: 30 % of tickets are label refunds; refunds under €20 cost more to process than they are worth | E35: Work avoided; the cost of error is refund leakage
B36: P5 · Ed-tech LMS | C36: 14 countries · 6 languages · 20 agents (volume not given: estimate it) | D36: Tickets in Portuguese, Polish, Arabic wait 2–3× longer | E36: Work avoided — use the categories for languages
B37: P6 · Project-management SaaS | C37: 30,000 SMB accounts · 9,000 tickets/month · 8 % annual churn | D37: Churn signals visible in support weeks before cancellation | E37: Work avoided + revenue retained (Other value)
B38: P7 · Cybersecurity SaaS | C38: 400 enterprise accounts · 6,000 tickets/month · 25 engineers · SLA P1 = 1 h, P2 = 4 h | D38: Misprioritised tickets cause SLA breaches and penalties | E38: Time saved + penalties avoided (Other value)
B39: P8 · Hospitality-tech | C39: 3,000 hotels (volume not given: estimate it) · reviews.csv for real data | D39: 20 % of tickets are analysis requests; answer today in 4 days | E39: Time saved — analysis requests answered faster
B40: Own project | C40: The numbers of your 00_pitch.md | D40: Your pain, expressed as a cost | E40: Pick the kind of value below; invent plausible numbers and label them
B42: NOT ONLY TICKETS — OTHER KINDS OF VALUE, WITH WORKED EXAMPLES
B43: Every agent is sized the same way: volume × share in scope × success rate × value per success − AI cost − cost of errors − fixed costs. Only the unit and the value change. Pick the line that matches your agent (you can combine two). Numbers below are illustrative — replace them with yours.
B44: Kind of value | C44: Typical for | D44: What goes where in the sheet | E44: Illustrative example
B45: Work avoided (deflection) | C45: P1, P4, P5 | D45: Volume = tickets · success rate = deflection · value per unit = human cost of one ticket. | E45: P1: 40,000 tickets × 55 % “how do I” × 68 % automatable × your deflection rate (say 50 %) × €10 ≈ €75k a month at full adoption.
B46: Time saved (copilot) | C46: P2, P7 (triage), P8 | D46: Volume = tickets or requests the agent helps with · success rate = share of handling time saved · value per unit = human cost of one. | E46: P2: 12,000 tickets × 100 % with the copilot × 20 % of time saved × €10 ≈ €24k a month.
B47: Revenue retained | C47: P6 | D47: Use an Other value row (67–68): accounts at risk that reach support × share saved × yearly revenue per account. | E47: P6: 30,000 accounts × 8 % churn = 2,400 lost a year; half open a ticket first; 10 % saved = 120 × €1,200 ≈ €144k a year.
B48: Penalties avoided | C48: P7 | D48: Use an Other value row: breaches a year × share avoided × penalty per breach (from the contracts). | E48: P7: 240 SLA breaches a year × 30 % avoided × €2,000 ≈ €144k a year.
B49: Faster answers, incident load | C49: P3, P8 | D49: Volume = requests or incident tickets (incidents a year × tickets per incident ÷ 12) · value = agent time per ticket; the speed gain goes in the memo. | E49: P3: 20 incidents a year × 1,500 tickets each ÷ 12 = 2,500 tickets a month.
...

Sheet Inputs
A1: 02_sizing — CyberSLA · SLA-aware alert prioritisation agent, B2B cybersecurity SaaS · Inputs
A2: Template for Assignment 2. Fill the yellow cells (Low / Base / High, Source type). Black cells are formulas — do not type over them. 'Low' = pessimistic scenario throughout (lower value, higher cost and error rates); 'High' = optimistic. Column H shows the class exercise (Paylio, a fictional company) as an example of format only — your numbers are those of YOUR team's project. Step-by-step guide in the first tab.
A4: Parameter | B4: Unit | C4: Low (pessimistic) | D4: Base | E4: High (optimistic) | F4: Source type | G4: Note / where the number comes from | H4: Example only — class exercise (Paylio, base)
A5: VOLUME AND HUMAN COST
A6: Volume per month (tickets, requests, conversations…) | B6: tickets | C6: 20000 | D6: 28800 | E6: 34560 | F6: measured (benchmark) | G6: 01_problem_statement: 960 alerts/day average (Prophet Security AI in SOC Survey 2025) → 28,800/month. Low = 20,000 (README figure). High = base + 20 % (01: alert volume +20 %/yr, Gurucul 2025, N-able 2026). | H6: 40000
A7: Tier-1 support agents (headcount) | B7: people | C7: 10 | D7: 10 | E7: 10 | F7: measured (benchmark) | G7: 01: 8–10 analysts for 24×7 coverage (Expel 2026). NB README says 40 analysts — team to align on ONE number. | H7: 60
A8: Cost of ONE agent to the company per year (all-in) | B8: € / year | C8: 300000 | D8: 270000 | E8: 225000 | F8: analogy | G8: 01: €75–90k salary (DVF Recruitment 2025) × 2.5–3 fully loaded, 24/7 shift premium → €225–300k. | H8: 45000
A9: Cost of ONE unit handled by a human (ticket, request…) | B9: € / ticket | C9: 6 | D9: 8 | E9: 10 | F9: analogy | G9: Fully loaded analyst time per alert triaged. Check row 10: 10 × €270k ÷ 345,600 alerts/yr ≈ €7.8. Low/high ±25 %. To check: time the triage of 50 alerts. | H9: 10
A10: Check — cost per ticket from headcount, base = agents × cost per agent ÷ tickets per year | B10: € / ticket | D10: =IFERROR(D7*D8/(D6*12),"") -> 7.8125 | G10: Formula, not an input: agents × cost per agent ÷ (volume × 12) = the agent time per unit. Row 9 should be equal or higher (Paylio: €5.6 of agent time, €10 all-in).
A11: Check — tickets per agent per working day, base (21 working days a month) | B11: tickets | D11: =IFERROR(D6/D7/21,"") -> 137.14286 | G11: Formula, not an input: volume ÷ agents ÷ 21 — a sanity check (Paylio ≈ 32 tickets a day).
A12: TICKET CATEGORIES
A13: Share of the volume by category (rename the three categories in A14:A16 — the other blocks follow)
A14: Low-severity & false-positive alerts (noise) | B14: share | C14: 0.6 | D14: 0.6 | E14: 0.6 | F14: analogy | G14: Prophet Security 2025: 40 % of alerts left uninvestigated, most of them noise; we assume 60 % low/false-positive. To measure on the S4 dataset (00_datasource_links.md, priority field). | H14: 0.55
A15: Medium / high alerts needing investigation | B15: share | C15: 0.35 | D15: 0.35 | E15: 0.35 | F15: guess | G15: Remainder minus critical. Measure on the S4 dataset. | H15: 0.3
A16: Critical alerts (SLA ≤ 1–3 h) | B16: share | C16: 0.05 | D16: 0.05 | E16: 0.05 | F16: guess | G16: Critical share — drives the tail risk. Measure on the S4 dataset (P1 share). | H16: 0.15
A17: Automatable share (answerable from documentation)
A18: =" "&TRIM($A$14) -> Low-severity & false-positive alerts (noise) | B18: share | C18: 0.6 | D18: 0.7 | E18: 0.8 | F18: guess | G18: Share of noise alerts the agent can enrich and rank (SLA + severity + asset context available). Test: 200 alerts of the S4 dataset. | H18: 0.68
A19: =" "&TRIM($A$15) -> Medium / high alerts needing investigation | B19: share | C19: 0.4 | D19: 0.5 | E19: 0.6 | F19: guess | G19: Investigations: the agent pre-gathers context for half of them. Test on 200 alerts. | H19: 0.15
A20: =" "&TRIM($A$16) -> Critical alerts (SLA ≤ 1–3 h) | B20: share | C20: 0.3 | D20: 0.4 | E20: 0.5 | F20: guess | G20: Not valued (out of scope, row 36). | H20: 0.35
A21: Success rate on the automatable share (deflection — or share of time saved, see the guide)
A22: =" "&TRIM($A$14) -> Low-severity & false-positive alerts (noise) | B22: share | C22: 0.3 | D22: 0.45 | E22: 0.6 | F22: guess → S4 test | G22: COPILOT, not deflection: share of analyst triage time saved on noise when the queue arrives pre-ranked and explained. THE flip assumption — timed with vs without the agent on 200 alerts in S4. | H22: your guess: 30–80 %
A23: =" "&TRIM($A$15) -> Medium / high alerts needing investigation | B23: share | C23: 0.15 | D23: 0.25 | E23: 0.35 | F23: guess → S4 test | G23: Share of investigation time saved by the pre-gathered context (asset, SLA clock, similar past alerts). | H23: your guess: lower — harder questions
A24: =" "&TRIM($A$16) -> Critical alerts (SLA ≤ 1–3 h) | B24: share | C24: 0 | D24: 0 | E24: 0 | F24: decision | G24: Critical alerts: no time-saving claimed — the analyst handles them fully. | H24: your guess
A25: Error rate — share of AI answers that are wrong
A26: =" "&TRIM($A$14) -> Low-severity & false-positive alerts (noise) | B26: share | C26: 0.05 | D26: 0.03 | E26: 0.02 | F26: guess | G26: Share of noise alerts ranked too low (a real threat hidden in noise). Eval-set in S5. | H26: 0.04
A27: =" "&TRIM($A$15) -> Medium / high alerts needing investigation | B27: share | C27: 0.08 | D27: 0.05 | E27: 0.03 | F27: guess | G27: Share of investigations ranked too low. Eval-set in S5. | H27: 0.06
A28: =" "&TRIM($A$16) -> Critical alerts (SLA ≤ 1–3 h) | B28: share | C28: 0.05 | D28: 0.03 | E28: 0.02 | F28: guess | G28: Not valued (out of scope). | H28: 0.05
A29: Cost of one wrong answer
A30: =" "&TRIM($A$14) -> Low-severity & false-positive alerts (noise) | B30: € / error | C30: 150 | D30: 80 | E30: 40 | F30: judgement | G30: Re-triage later + small chance of a late real threat. The catastrophic case is priced separately (row 68 + governance.md). | H30: a few € (asks again)
A31: =" "&TRIM($A$15) -> Medium / high alerts needing investigation | B31: € / error | C31: 200 | D31: 120 | E31: 60 | F31: judgement | G31: Investigation started late: analyst time + SLA clock lost. | H31: hundreds of € (penalty)
A32: =" "&TRIM($A$16) -> Critical alerts (SLA ≤ 1–3 h) | B32: € / error | C32: 0 | D32: 0 | E32: 0 | F32: n/a | G32: Out of scope. | H32: tens of € (refund)
A33: Include category in scope? (1 = yes, 0 = no)
A34: =" "&TRIM($A$14) -> Low-severity & false-positive alerts (noise) | B34: 1/0 | C34: 1 | D34: 1 | E34: 1 | F34: decision | G34: In scope: agent ranks and explains (L4 internal); analyst decides. | H34: 1
A35: =" "&TRIM($A$15) -> Medium / high alerts needing investigation | B35: 1/0 | C35: 1 | D35: 1 | E35: 1 | F35: decision | G35: In scope: agent pre-gathers context; analyst investigates. | H35: 1
A36: =" "&TRIM($A$16) -> Critical alerts (SLA ≤ 1–3 h) | B36: 1/0 | C36: 0 | D36: 0 | E36: 0 | F36: decision | G36: EXCLUDED: critical alerts go straight to the on-call analyst. The agent may RAISE a priority, never lower it (governance.md, guardrail 4). | H36: 1
A38: ADOPTION RAMP — share of deflectable volume actually handled, by quarter
A39: Q1 | B39: share | C39: 0.1 | D39: 0.2 | E39: 0.3 | F39: decision | G39: Staged rollout (one shift, then 24×7); each step only if critical-alert recall on the eval replay stays ≥ 99 %. | H39: 0.2
A40: Q2 | B40: share | C40: 0.2 | D40: 0.4 | E40: 0.5 | F40: decision | G40: Staged rollout (one shift, then 24×7); each step only if critical-alert recall on the eval replay stays ≥ 99 %. | H40: 0.4
A41: Q3 | B41: share | C41: 0.35 | D41: 0.6 | E41: 0.7 | F41: decision | G41: Staged rollout (one shift, then 24×7); each step only if critical-alert recall on the eval replay stays ≥ 99 %. | H41: 0.6
A42: Q4 | B42: share | C42: 0.5 | D42: 0.7 | E42: 0.8 | F42: decision | G42: Staged rollout (one shift, then 24×7); each step only if critical-alert recall on the eval replay stays ≥ 99 %. | H42: 0.7
...

Sheet Upside
A1: 02_sizing — your agent · Upside (bottom-up tree per category, year 1)
A2: All cells are formulas linked to Inputs (green = link to another sheet). Read each block top to bottom: it is the tree from the S2 slides, per ticket category.
A4: Line | B4: Unit | C4: Low | D4: Base | E4: High | F4: How it is computed
A5: Year-1 adoption factor (average of the four quarters) | C5: =IFERROR(AVERAGE(Inputs!C39:C42),0) -> 0.2875 | D5: =IFERROR(AVERAGE(Inputs!D39:D42),0) -> 0.475 | E5: =IFERROR(AVERAGE(Inputs!E39:E42),0) -> 0.575 | F5: → AVERAGE(Inputs ramp Q1..Q4)
A7: =UPPER(TRIM(Inputs!A14)) -> LOW-SEVERITY & FALSE-POSITIVE ALERTS (NOISE)
A8: Tickets per month in this category | B8: tickets | C8: =Inputs!C$6*Inputs!C14 -> 12000 | D8: =Inputs!D$6*Inputs!D14 -> 17280 | E8: =Inputs!E$6*Inputs!E14 -> 20736 | F8: → tickets/month × share
A9: Automatable tickets per month | B9: tickets | C9: =C8*Inputs!C18 -> 7200 | D9: =D8*Inputs!D18 -> 12096 | E9: =E8*Inputs!E18 -> 16588.8 | F9: × automatable share
A10: Deflected per month at steady state (if in scope) | B10: tickets | C10: =C9*Inputs!C22*Inputs!C34 -> 2160 | D10: =D9*Inputs!D22*Inputs!D34 -> 5443.2 | E10: =E9*Inputs!E22*Inputs!E34 -> 9953.28 | F10: × deflection realised × include flag
A11: Deflected in year 1, with the adoption ramp | B11: tickets / yr | C11: =C10*12*C$5 -> 7452 | D11: =D10*12*D$5 -> 31026.24 | E11: =E10*12*E$5 -> 68677.632 | F11: × 12 × year-1 adoption factor
A12: Gross value — human work avoided | B12: € / yr | C12: =C11*Inputs!C$9 -> 44712 | D12: =D11*Inputs!D$9 -> 248209.92 | E12: =E11*Inputs!E$9 -> 686776.32 | F12: × fully loaded cost of a human ticket
A13: Expected cost of wrong answers | B13: € / yr | C13: =C11*Inputs!C26*Inputs!C30 -> 55890 | D13: =D11*Inputs!D26*Inputs!D30 -> 74462.976 | E13: =E11*Inputs!E26*Inputs!E30 -> 54942.106 | F13: deflected × error rate × cost of one wrong answer — the tail, priced
A14: AI handling cost (tokens, retries) | B14: € / yr | C14: =C11*Inputs!C$45*Inputs!C$46 -> 968.76 | D14: =D11*Inputs!D$45*Inputs!D$46 -> 1861.5744 | E14: =E11*Inputs!E$45*Inputs!E$46 -> 1510.9079 | F14: deflected × cost per conversation × retry overhead
A15: Net contribution of this category | B15: € / yr | C15: =C12-C13-C14 -> -12146.76 | D15: =D12-D13-D14 -> 171885.37 | E15: =E12-E13-E14 -> 630323.31 | F15: gross − error cost − AI cost
A17: =UPPER(TRIM(Inputs!A15)) -> MEDIUM / HIGH ALERTS NEEDING INVESTIGATION
A18: Tickets per month in this category | B18: tickets | C18: =Inputs!C$6*Inputs!C15 -> 7000 | D18: =Inputs!D$6*Inputs!D15 -> 10080 | E18: =Inputs!E$6*Inputs!E15 -> 12096 | F18: → tickets/month × share
A19: Automatable tickets per month | B19: tickets | C19: =C18*Inputs!C19 -> 2800 | D19: =D18*Inputs!D19 -> 5040 | E19: =E18*Inputs!E19 -> 7257.6 | F19: × automatable share
A20: Deflected per month at steady state (if in scope) | B20: tickets | C20: =C19*Inputs!C23*Inputs!C35 -> 420 | D20: =D19*Inputs!D23*Inputs!D35 -> 1260 | E20: =E19*Inputs!E23*Inputs!E35 -> 2540.16 | F20: × deflection realised × include flag
A21: Deflected in year 1, with the adoption ramp | B21: tickets / yr | C21: =C20*12*C$5 -> 1449 | D21: =D20*12*D$5 -> 7182 | E21: =E20*12*E$5 -> 17527.104 | F21: × 12 × year-1 adoption factor
A22: Gross value — human work avoided | B22: € / yr | C22: =C21*Inputs!C$9 -> 8694 | D22: =D21*Inputs!D$9 -> 57456 | E22: =E21*Inputs!E$9 -> 175271.04 | F22: × fully loaded cost of a human ticket
A23: Expected cost of wrong answers | B23: € / yr | C23: =C21*Inputs!C27*Inputs!C31 -> 23184 | D23: =D21*Inputs!D27*Inputs!D31 -> 43092 | E23: =E21*Inputs!E27*Inputs!E31 -> 31548.787 | F23: deflected × error rate × cost of one wrong answer — the tail, priced
A24: AI handling cost (tokens, retries) | B24: € / yr | C24: =C21*Inputs!C$45*Inputs!C$46 -> 188.37 | D24: =D21*Inputs!D$45*Inputs!D$46 -> 430.92 | E24: =E21*Inputs!E$45*Inputs!E$46 -> 385.59629 | F24: deflected × cost per conversation × retry overhead
A25: Net contribution of this category | B25: € / yr | C25: =C22-C23-C24 -> -14678.37 | D25: =D22-D23-D24 -> 13933.08 | E25: =E22-E23-E24 -> 143336.66 | F25: gross − error cost − AI cost
A27: =UPPER(TRIM(Inputs!A16)) -> CRITICAL ALERTS (SLA ≤ 1–3 H)
A28: Tickets per month in this category | B28: tickets | C28: =Inputs!C$6*Inputs!C16 -> 1000 | D28: =Inputs!D$6*Inputs!D16 -> 1440 | E28: =Inputs!E$6*Inputs!E16 -> 1728 | F28: → tickets/month × share
A29: Automatable tickets per month | B29: tickets | C29: =C28*Inputs!C20 -> 300 | D29: =D28*Inputs!D20 -> 576 | E29: =E28*Inputs!E20 -> 864 | F29: × automatable share
A30: Deflected per month at steady state (if in scope) | B30: tickets | C30: =C29*Inputs!C24*Inputs!C36 -> 0 | D30: =D29*Inputs!D24*Inputs!D36 -> 0 | E30: =E29*Inputs!E24*Inputs!E36 -> 0 | F30: × deflection realised × include flag
A31: Deflected in year 1, with the adoption ramp | B31: tickets / yr | C31: =C30*12*C$5 -> 0 | D31: =D30*12*D$5 -> 0 | E31: =E30*12*E$5 -> 0 | F31: × 12 × year-1 adoption factor
A32: Gross value — human work avoided | B32: € / yr | C32: =C31*Inputs!C$9 -> 0 | D32: =D31*Inputs!D$9 -> 0 | E32: =E31*Inputs!E$9 -> 0 | F32: × fully loaded cost of a human ticket
A33: Expected cost of wrong answers | B33: € / yr | C33: =C31*Inputs!C28*Inputs!C32 -> 0 | D33: =D31*Inputs!D28*Inputs!D32 -> 0 | E33: =E31*Inputs!E28*Inputs!E32 -> 0 | F33: deflected × error rate × cost of one wrong answer — the tail, priced
A34: AI handling cost (tokens, retries) | B34: € / yr | C34: =C31*Inputs!C$45*Inputs!C$46 -> 0 | D34: =D31*Inputs!D$45*Inputs!D$46 -> 0 | E34: =E31*Inputs!E$45*Inputs!E$46 -> 0 | F34: deflected × cost per conversation × retry overhead
A35: Net contribution of this category | B35: € / yr | C35: =C32-C33-C34 -> 0 | D35: =D32-D33-D34 -> 0 | E35: =E32-E33-E34 -> 0 | F35: gross − error cost − AI cost
A37: TOTALS — ALL CATEGORIES IN SCOPE
A38: Tickets deflected in year 1 | B38: tickets / yr | C38: =C11+C21+C31 -> 8901 | D38: =D11+D21+D31 -> 38208.24 | E38: =E11+E21+E31 -> 86204.736 | F38: sum of the three categories
A39: Gross value — human work avoided | B39: € / yr | C39: =C12+C22+C32 -> 53406 | D39: =D12+D22+D32 -> 305665.92 | E39: =E12+E22+E32 -> 862047.36 | F39: sum of the three categories
A40: Expected cost of wrong answers | B40: € / yr | C40: =C13+C23+C33 -> 79074 | D40: =D13+D23+D33 -> 117554.98 | E40: =E13+E23+E33 -> 86490.893 | F40: sum of the three categories
A41: AI handling cost | B41: € / yr | C41: =C14+C24+C34 -> 1157.13 | D41: =D14+D24+D34 -> 2292.4944 | E41: =E14+E24+E34 -> 1896.5042 | F41: sum of the three categories
A42: Net variable contribution (before fixed costs) | B42: € / yr | C42: =C15+C25+C35 -> -26825.13 | D42: =D15+D25+D35 -> 185818.45 | E42: =E15+E25+E35 -> 773659.96 | F42: sum of the three categories
A44: Share of all tickets deflected in year 1 | B44: share | C44: =IF(Inputs!C6=0,0,C38/(Inputs!C6*12)) -> 0.0370875 | D44: =IF(Inputs!D6=0,0,D38/(Inputs!D6*12)) -> 0.11055625 | E44: =IF(Inputs!E6=0,0,E38/(Inputs!E6*12)) -> 0.2078625 | F44: sanity check: the SOM in ticket terms

Sheet Decision
A1: 02_sizing — your agent · Costs & Decision
A2: Three scenarios → expected value → two comparisons (do-nothing, hurdle). Green = links to Upside / Inputs; black = formulas.
A4: Line | B4: Unit | C4: Low (pessimistic) | D4: Base | E4: High (optimistic) | F4: How it is computed
A5: VALUE
A6: Net variable contribution (Upside) + other value (Inputs rows 67–68) | B6: € / yr | C6: =Upside!C42+N(Inputs!C67)+N(Inputs!C68) -> -45225.13 | D6: =Upside!D42+N(Inputs!D67)+N(Inputs!D68) -> 253918.45 | E6: =Upside!E42+N(Inputs!E67)+N(Inputs!E68) -> 912459.96 | F6: gross − error cost − AI cost, all categories in scope
A8: FIXED AND SEMI-FIXED COSTS
A9: Integration, amortised | B9: € / yr | C9: =IFERROR(Inputs!C49/Inputs!C50,0) -> 73333.333 | D9: =IFERROR(Inputs!D49/Inputs!D50,0) -> 50000 | E9: =IFERROR(Inputs!E49/Inputs!E50,0) -> 33333.333 | F9: one-off ÷ amortisation years
A10: Evaluation — eval-set and graders | B10: € / yr | C10: =Inputs!C51 -> 70000 | D10: =Inputs!D51 -> 50000 | E10: =Inputs!E51 -> 35000
A11: Supervision — humans in the loop | B11: € / yr | C11: =Inputs!C52*Inputs!C53 -> 225000 | D11: =Inputs!D52*Inputs!D53 -> 150000 | E11: =Inputs!E52*Inputs!E53 -> 75000 | F11: FTE × cost per FTE
A12: Monitoring and on-call | B12: € / yr | C12: =Inputs!C54 -> 70000 | D12: =Inputs!D54 -> 55000 | E12: =Inputs!E54 -> 40000
A13: Re-evaluation at model changes | B13: € / yr | C13: =Inputs!C55*Inputs!C56 -> 40000 | D13: =Inputs!D55*Inputs!D56 -> 28000 | E13: =Inputs!E55*Inputs!E56 -> 20000 | F13: changes per year × cost per change
A14: Total fixed and semi-fixed | B14: € / yr | C14: =SUM(C9:C13) -> 478333.33 | D14: =SUM(D9:D13) -> 333000 | E14: =SUM(E9:E13) -> 203333.33
A16: NET ANNUAL VALUE AND EXPECTED VALUE
A17: Net annual value of the project, year 1 | B17: € / yr | C17: =C6-C14 -> -523558.46 | D17: =D6-D14 -> -79081.55 | E17: =E6-E14 -> 709126.63 | F17: net variable contribution − fixed costs
A18: Scenario probability | B18: p | C18: =Inputs!C63 -> 0.3 | D18: =Inputs!D63 -> 0.5 | E18: =Inputs!E63 -> 0.2 | F18: from Inputs
A19: Expected value (Σ p × net value) | B19: € / yr | D19: =SUMPRODUCT(C17:E17,C18:E18) -> -54782.988 | F19: the single number — but read the three above it first
A21: THE TWO COMPARISONS
A22: Do-nothing: value of the current process improving on its own | B22: € / yr | C22: =Inputs!C59*Inputs!C6*12*Inputs!C9 -> 43200 | D22: =Inputs!D59*Inputs!D6*12*Inputs!D9 -> 138240 | E22: =Inputs!E59*Inputs!E6*12*Inputs!E9 -> 207360 | F22: efficiency gain × annual tickets × cost per ticket — not zero
A23: Next-best project (the hurdle) | B23: € / yr | C23: =Inputs!C60 -> 100000 | D23: =Inputs!D60 -> 100000 | E23: =Inputs!E60 -> 100000 | F23: from Inputs
A24: EV minus do-nothing | B24: € / yr | D24: =D19-D22 -> -193022.99
A25: EV minus hurdle | B25: € / yr | D25: =D19-D23 -> -154782.99
A26: Pessimistic case clears the hurdle? | D26: =IF(C17>=C23,"yes","no") -> no
A27: Decision (formula — you still write the memo) | D27: =IF(Inputs!D6="","— fill in the Inputs tab first —",IF(ABS(Inputs!D64-1)>0.001,"— scenario probabilities must sum to 1 —",IF(D19<D22,"NO-GO — does not beat do-nothing",IF(D19<D23,"NO-GO — does not beat the next-best project",IF(C17<D23,"CONDITIONAL GO — EV clears the hurdle, the pessimistic case does not: test the deflection assumption first","GO"))))) -> NO-GO — does not beat do-nothing
A29: SENSITIVITY — the assumption that flips the decision
A30: Base case, varying only the deflection realised on category 1 (row 22 of Inputs). Everything else at Base.
A31: Deflection on “How do I…” | C31: Net annual value | D31: vs hurdle | E31: vs do-nothing | F31: Reading
A32: 0.3 | C32: =((Upside!D9*A32*Inputs!D34*12*Upside!D$5)*Inputs!D$9-(Upside!D9*A32*Inputs!D34*12*Upside!D$5)*Inputs!D26*Inputs!D30-(Upside!D9*A32*Inputs!D34*12*Upside!D$5)*Inputs!D$45*Inputs!D$46)+Upside!D25+Upside!D35-D14+N(Inputs!$D$67)+N(Inputs!$D$68) -> -136376.67 | D32: =C32-D23 -> -236376.67 | E32: =C32-D22 -> -274616.67 | F32: =IF(Inputs!D6="","",IF(C32<D22,"below do-nothing",IF(C32<D23,"below the hurdle — the next-best project wins","clears the hurdle"))) -> below do-nothing
A33: 0.45 | C33: =((Upside!D9*A33*Inputs!D34*12*Upside!D$5)*Inputs!D$9-(Upside!D9*A33*Inputs!D34*12*Upside!D$5)*Inputs!D26*Inputs!D30-(Upside!D9*A33*Inputs!D34*12*Upside!D$5)*Inputs!D$45*Inputs!D$46)+Upside!D25+Upside!D35-D14+N(Inputs!$D$67)+N(Inputs!$D$68) -> -79081.55 | D33: =C33-D23 -> -179081.55 | E33: =C33-D22 -> -217321.55 | F33: =IF(Inputs!D6="","",IF(C33<D22,"below do-nothing",IF(C33<D23,"below the hurdle — the next-best project wins","clears the hurdle"))) -> below do-nothing
A34: 0.6 | C34: =((Upside!D9*A34*Inputs!D34*12*Upside!D$5)*Inputs!D$9-(Upside!D9*A34*Inputs!D34*12*Upside!D$5)*Inputs!D26*Inputs!D30-(Upside!D9*A34*Inputs!D34*12*Upside!D$5)*Inputs!D$45*Inputs!D$46)+Upside!D25+Upside!D35-D14+N(Inputs!$D$67)+N(Inputs!$D$68) -> -21786.427 | D34: =C34-D23 -> -121786.43 | E34: =C34-D22 -> -160026.43 | F34: =IF(Inputs!D6="","",IF(C34<D22,"below do-nothing",IF(C34<D23,"below the hurdle — the next-best project wins","clears the hurdle"))) -> below do-nothing
A35: 0.65 | C35: =((Upside!D9*A35*Inputs!D34*12*Upside!D$5)*Inputs!D$9-(Upside!D9*A35*Inputs!D34*12*Upside!D$5)*Inputs!D26*Inputs!D30-(Upside!D9*A35*Inputs!D34*12*Upside!D$5)*Inputs!D$45*Inputs!D$46)+Upside!D25+Upside!D35-D14+N(Inputs!$D$67)+N(Inputs!$D$68) -> -2688.0528 | D35: =C35-D23 -> -102688.05 | E35: =C35-D22 -> -140928.05 | F35: =IF(Inputs!D6="","",IF(C35<D22,"below do-nothing",IF(C35<D23,"below the hurdle — the next-best project wins","clears the hurdle"))) -> below do-nothing
A36: 0.75 | C36: =((Upside!D9*A36*Inputs!D34*12*Upside!D$5)*Inputs!D$9-(Upside!D9*A36*Inputs!D34*12*Upside!D$5)*Inputs!D26*Inputs!D30-(Upside!D9*A36*Inputs!D34*12*Upside!D$5)*Inputs!D$45*Inputs!D$46)+Upside!D25+Upside!D35-D14+N(Inputs!$D$67)+N(Inputs!$D$68) -> 35508.696 | D36: =C36-D23 -> -64491.304 | E36: =C36-D22 -> -102731.3 | F36: =IF(Inputs!D6="","",IF(C36<D22,"below do-nothing",IF(C36<D23,"below the hurdle — the next-best project wins","clears the hurdle"))) -> below do-nothing
A38: Read down the table: the deflection rate at which the reading changes is your flip point. Name it in the memo — it is the number your S4 prototype must measure.

Sheet Build or buy
A1: 02_sizing — your agent · Build, buy or orchestrate?
A2: Score each option from 1 (bad) to 5 (good) on each question, weight what matters to your company (weights sum to 100 %). Then write one line in the memo — “We orchestrate because…” — and the condition that would change it. See the build / buy / orchestrate slides of Session 2 (39–40).
A4: # | B4: Question | C4: Weight | D4: Build | E4: Buy | F4: Orchestrate | G4: Why — one line per score that is not obvious
A5: 01 | B5: Strategy — Is it our edge? Would a competitor buying the same tool erase our advantage? | C5: 0.1 | D5: 4 | E5: 2 | F5: 4 | G5: Ranking learned on OUR alerts + customers' SLA contracts is the edge; an AI-SOC vendor gives every competitor the same.
A6: 02 | B6: Strategy — Do we own data or know-how that no vendor has? | C6: 0.1 | D6: 4 | E6: 2 | F6: 5 | G6: SLA contracts per customer + resolved-alert history = data no vendor has.
A7: 03 | B7: Fit & speed — Does a product already do 80 % of the job — our languages, channels, integrations? | C7: 0.05 | D7: 1 | E7: 4 | F7: 3 | G7: AI-SOC triage products exist (enrichment, ranking) — but not SLA-contract-aware.
A8: 04 | B8: Fit & speed — Must it be live in weeks, or can it take quarters? | C8: 0.05 | D8: 1 | E8: 4 | F8: 3 | G8: Buy is fastest; orchestration on open-weights + our SOAR in one quarter.
A9: 05 | B9: Fit & speed — Do we have the people to build it and to run it — evals, on-call, re-evaluation? | C9: 0.1 | D9: 2 | E9: 4 | F9: 3 | G9: 10 analysts, no ML team: build needs people we do not have.
A10: 06 | B10: Money — 3-year total cost: fees per resolution or per seat vs the seven cost lines of a build | C10: 0.1 | D10: 2 | E10: 3 | F10: 4 | G10: 3-yr: orchestration avoids per-alert fees and a full in-house model.
A11: 07 | B11: Money — At what volume does per-resolution pricing cost more than building? (break-even below) | C11: 0.05 | D11: 3 | E11: 2 | F11: 4 | G11: See break-even below.
A12: 08 | B12: Risk & control — Where does our data go — GDPR, residency, may the vendor train on it? | C12: 0.2 | D12: 5 | E12: 1 | F12: 5 | G12: Logs cannot leave our perimeter: SaaS AI-SOC tools that send alerts to a third-party API are a deal-breaker for our customers.
A13: 09 | B13: Risk & control — Can we leave — exit clause, export of data, prompts and eval-sets? | C13: 0.1 | D13: 4 | E13: 2 | F13: 4 | G13: We keep prompts, eval-sets and ranking rules; lock-in on buy.
A14: 10 | B14: Risk & control — Who is liable when it is wrong, and can we see why it answered — logs, evals? | C14: 0.15 | D14: 4 | E14: 2 | F14: 4 | G14: We must show WHY an alert got its rank (audit, CISO) — our logs and evals, not a vendor black box.
B16: Weights must sum to 100 % | C16: =SUM(C5:C14) -> 1
B17: Weighted score (1–5) | D17: =IFERROR(IF(COUNT(D5:D14)=0,"",SUMPRODUCT($C$5:$C$14,D5:D14)/SUM($C$5:$C$14)),"") -> 3.45 | E17: =IFERROR(IF(COUNT(E5:E14)=0,"",SUMPRODUCT($C$5:$C$14,E5:E14)/SUM($C$5:$C$14)),"") -> 2.3 | F17: =IFERROR(IF(COUNT(F5:F14)=0,"",SUMPRODUCT($C$5:$C$14,F5:F14)/SUM($C$5:$C$14)),"") -> 4.1
B18: Highest weighted score | D18: =IF(COUNT(D17:F17)=0,"— score the three options —",IF(ABS(C16-1)>0.001,"— weights must sum to 100 % —",INDEX($D$4:$F$4,MATCH(MAX(D17:F17),D17:F17,0)))) -> Orchestrate | G18: The score informs the decision; the memo makes it. If two options are within 0.3, say which condition would decide.
A21: BREAK-EVEN — buying per resolution vs running it yourself (base case, rough)
B22: Vendor price per resolution | D22: 0.5 | E22: € / resolution | G22: guess — AI-SOC vendors do not publish per-alert prices; replace with a quote
B23: Tickets deflected in year 1 (base) | D23: =Upside!D38 -> 38208.24 | E23: tickets / yr | G23: from Upside
B24: Annual vendor fees | D24: =IFERROR(D22*D23,0) -> 19104.12 | E24: € / yr | G24: price × resolutions
B25: Your own AI handling cost (tokens, retries) | D25: =Upside!D41 -> 2292.4944 | E25: € / yr | G25: from Upside
B26: Integration (amortised) + evaluation + re-evaluation | D26: =Decision!D9+Decision!D10+Decision!D13 -> 128000 | E26: € / yr | G26: from Decision — the build-specific fixed lines
B27: Running it yourself — comparable cost | D27: =D25+D26 -> 130292.49 | E27: € / yr | G27: supervision and monitoring stay in both options, so they are left out
B28: Buying is cheaper by | D28: =D27-D24 -> 111188.37 | E28: € / yr | G28: negative = running it yourself is cheaper at this volume
